Watching for file changes with StatReloader
Internal Server Error: /
Traceback (most recent call last):
  File "/Library/Frameworks/Python.framework/Versions/3.11/lib/python3.11/site-packages/django/core/handlers/exception.py", line 55, in inner
    response = get_response(request)
               ^^^^^^^^^^^^^^^^^^^^^
  File "/Library/Frameworks/Python.framework/Versions/3.11/lib/python3.11/site-packages/django/core/handlers/base.py", line 197, in _get_response
    response = wrapped_callback(request, *callback_args, **callback_kwargs)
               ^^^^^^^^^^^^^^^^^^^^^^^^^^^^^^^^^^^^^^^^^^^^^^^^^^^^^^^^^^^^
  File "/Users/tako/Desktop/step/django/hw_13_10_2/myproject/myapp/views.py", line 9, in home
    return render(request, 'home.html')
           ^^^^^^^^^^^^^^^^^^^^^^^^^^^^
  File "/Library/Frameworks/Python.framework/Versions/3.11/lib/python3.11/site-packages/django/shortcuts.py", line 24, in render
    content = loader.render_to_string(template_name, context, request, using=using)
              ^^^^^^^^^^^^^^^^^^^^^^^^^^^^^^^^^^^^^^^^^^^^^^^^^^^^^^^^^^^^^^^^^^^^^
  File "/Library/Frameworks/Python.framework/Versions/3.11/lib/python3.11/site-packages/django/template/loader.py", line 61, in render_to_string
    template = get_template(template_name, using=using)
               ^^^^^^^^^^^^^^^^^^^^^^^^^^^^^^^^^^^^^^^^
  File "/Library/Frameworks/Python.framework/Versions/3.11/lib/python3.11/site-packages/django/template/loader.py", line 19, in get_template
    raise TemplateDoesNotExist(template_name, chain=chain)
django.template.exceptions.TemplateDoesNotExist: home.html
"GET / HTTP/1.1" 500 74944
Not Found: /apple-touch-icon-precomposed.png
"GET /apple-touch-icon-precomposed.png HTTP/1.1" 404 2676
Not Found: /apple-touch-icon.png
"GET /apple-touch-icon.png HTTP/1.1" 404 2640
"GET / HTTP/1.1" 200 251
"GET /login/ HTTP/1.1" 200 704
"POST /login/ HTTP/1.1" 200 769
Not Found: /lregister
"GET /lregister HTTP/1.1" 404 2607
"GET /register HTTP/1.1" 301 0
"GET /register/ HTTP/1.1" 200 719
"POST /register/ HTTP/1.1" 302 0
"GET /login/ HTTP/1.1" 200 704
"POST /login/ HTTP/1.1" 302 0
"GET / HTTP/1.1" 200 251
/Users/tako/Desktop/step/django/hw_13_10_2/myproject/myapp/views.py changed, reloading.
Watching for file changes with StatReloader
"GET /login/ HTTP/1.1" 200 704
"POST /login/ HTTP/1.1" 302 0
"GET / HTTP/1.1" 200 251
"GET /login HTTP/1.1" 301 0
"GET /login/ HTTP/1.1" 200 704
"POST /login/ HTTP/1.1" 302 0
"GET /register/ HTTP/1.1" 200 719
Watching for file changes with StatReloader
"GET / HTTP/1.1" 200 251
"GET /login/ HTTP/1.1" 200 704
"POST /login/ HTTP/1.1" 302 0
"GET /register/ HTTP/1.1" 200 719
Internal Server Error: /register/
Traceback (most recent call last):
  File "/Library/Frameworks/Python.framework/Versions/3.11/lib/python3.11/site-packages/django/db/backends/utils.py", line 89, in _execute
    return self.cursor.execute(sql, params)
           ^^^^^^^^^^^^^^^^^^^^^^^^^^^^^^^^
  File "/Library/Frameworks/Python.framework/Versions/3.11/lib/python3.11/site-packages/django/db/backends/sqlite3/base.py", line 328, in execute
    return super().execute(query, params)
           ^^^^^^^^^^^^^^^^^^^^^^^^^^^^^^
sqlite3.IntegrityError: UNIQUE constraint failed: myapp_customuser.username

The above exception was the direct cause of the following exception:

Traceback (most recent call last):
  File "/Library/Frameworks/Python.framework/Versions/3.11/lib/python3.11/site-packages/django/core/handlers/exception.py", line 55, in inner
    response = get_response(request)
               ^^^^^^^^^^^^^^^^^^^^^
  File "/Library/Frameworks/Python.framework/Versions/3.11/lib/python3.11/site-packages/django/core/handlers/base.py", line 197, in _get_response
    response = wrapped_callback(request, *callback_args, **callback_kwargs)
               ^^^^^^^^^^^^^^^^^^^^^^^^^^^^^^^^^^^^^^^^^^^^^^^^^^^^^^^^^^^^
  File "/Library/Frameworks/Python.framework/Versions/3.11/lib/python3.11/site-packages/django/views/generic/base.py", line 104, in view
    return self.dispatch(request, *args, **kwargs)
           ^^^^^^^^^^^^^^^^^^^^^^^^^^^^^^^^^^^^^^^
  File "/Library/Frameworks/Python.framework/Versions/3.11/lib/python3.11/site-packages/django/views/generic/base.py", line 143, in dispatch
    return handler(request, *args, **kwargs)
           ^^^^^^^^^^^^^^^^^^^^^^^^^^^^^^^^^
  File "/Users/tako/Desktop/step/django/hw_13_10_2(copie)/myproject/myapp/views.py", line 30, in post
    CustomUser.objects.create(username=username, password=password)
  File "/Library/Frameworks/Python.framework/Versions/3.11/lib/python3.11/site-packages/django/db/models/manager.py", line 87, in manager_method
    return getattr(self.get_queryset(), name)(*args, **kwargs)
           ^^^^^^^^^^^^^^^^^^^^^^^^^^^^^^^^^^^^^^^^^^^^^^^^^^^
  File "/Library/Frameworks/Python.framework/Versions/3.11/lib/python3.11/site-packages/django/db/models/query.py", line 658, in create
    obj.save(force_insert=True, using=self.db)
  File "/Library/Frameworks/Python.framework/Versions/3.11/lib/python3.11/site-packages/django/db/models/base.py", line 814, in save
    self.save_base(
  File "/Library/Frameworks/Python.framework/Versions/3.11/lib/python3.11/site-packages/django/db/models/base.py", line 877, in save_base
    updated = self._save_table(
              ^^^^^^^^^^^^^^^^^
  File "/Library/Frameworks/Python.framework/Versions/3.11/lib/python3.11/site-packages/django/db/models/base.py", line 1020, in _save_table
    results = self._do_insert(
              ^^^^^^^^^^^^^^^^
  File "/Library/Frameworks/Python.framework/Versions/3.11/lib/python3.11/site-packages/django/db/models/base.py", line 1061, in _do_insert
    return manager._insert(
           ^^^^^^^^^^^^^^^^
  File "/Library/Frameworks/Python.framework/Versions/3.11/lib/python3.11/site-packages/django/db/models/manager.py", line 87, in manager_method
    return getattr(self.get_queryset(), name)(*args, **kwargs)
           ^^^^^^^^^^^^^^^^^^^^^^^^^^^^^^^^^^^^^^^^^^^^^^^^^^^
  File "/Library/Frameworks/Python.framework/Versions/3.11/lib/python3.11/site-packages/django/db/models/query.py", line 1805, in _insert
    return query.get_compiler(using=using).execute_sql(returning_fields)
           ^^^^^^^^^^^^^^^^^^^^^^^^^^^^^^^^^^^^^^^^^^^^^^^^^^^^^^^^^^^^^
  File "/Library/Frameworks/Python.framework/Versions/3.11/lib/python3.11/site-packages/django/db/models/sql/compiler.py", line 1820, in execute_sql
    cursor.execute(sql, params)
  File "/Library/Frameworks/Python.framework/Versions/3.11/lib/python3.11/site-packages/django/db/backends/utils.py", line 102, in execute
    return super().execute(sql, params)
           ^^^^^^^^^^^^^^^^^^^^^^^^^^^^
  File "/Library/Frameworks/Python.framework/Versions/3.11/lib/python3.11/site-packages/django/db/backends/utils.py", line 67, in execute
    return self._execute_with_wrappers(
           ^^^^^^^^^^^^^^^^^^^^^^^^^^^^
  File "/Library/Frameworks/Python.framework/Versions/3.11/lib/python3.11/site-packages/django/db/backends/utils.py", line 80, in _execute_with_wrappers
    return executor(sql, params, many, context)
           ^^^^^^^^^^^^^^^^^^^^^^^^^^^^^^^^^^^^
  File "/Library/Frameworks/Python.framework/Versions/3.11/lib/python3.11/site-packages/django/db/backends/utils.py", line 84, in _execute
    with self.db.wrap_database_errors:
  File "/Library/Frameworks/Python.framework/Versions/3.11/lib/python3.11/site-packages/django/db/utils.py", line 91, in __exit__
    raise dj_exc_value.with_traceback(traceback) from exc_value
  File "/Library/Frameworks/Python.framework/Versions/3.11/lib/python3.11/site-packages/django/db/backends/utils.py", line 89, in _execute
    return self.cursor.execute(sql, params)
           ^^^^^^^^^^^^^^^^^^^^^^^^^^^^^^^^
  File "/Library/Frameworks/Python.framework/Versions/3.11/lib/python3.11/site-packages/django/db/backends/sqlite3/base.py", line 328, in execute
    return super().execute(query, params)
           ^^^^^^^^^^^^^^^^^^^^^^^^^^^^^^
django.db.utils.IntegrityError: UNIQUE constraint failed: myapp_customuser.username
"POST /register/ HTTP/1.1" 500 157421
"POST /register/ HTTP/1.1" 302 0
"GET /login/ HTTP/1.1" 200 704
"POST /login/ HTTP/1.1" 302 0
"GET / HTTP/1.1" 200 251
Watching for file changes with StatReloader
"GET / HTTP/1.1" 200 251
"GET /all_users HTTP/1.1" 301 0
"GET /all_users/ HTTP/1.1" 200 270
Not Found: /user_detail
"GET /user_detail HTTP/1.1" 404 2987
"GET /user_detail/1 HTTP/1.1" 301 0
"GET /user_detail/1/ HTTP/1.1" 200 224
"GET /user_detail/2/ HTTP/1.1" 200 222
"GET /all_users/ HTTP/1.1" 200 270
Watching for file changes with StatReloader
"GET / HTTP/1.1" 200 251
"GET /blog_posts HTTP/1.1" 301 0
Internal Server Error: /blog_posts/
Traceback (most recent call last):
  File "/Library/Frameworks/Python.framework/Versions/3.11/lib/python3.11/site-packages/django/db/backends/utils.py", line 89, in _execute
    return self.cursor.execute(sql, params)
           ^^^^^^^^^^^^^^^^^^^^^^^^^^^^^^^^
  File "/Library/Frameworks/Python.framework/Versions/3.11/lib/python3.11/site-packages/django/db/backends/sqlite3/base.py", line 328, in execute
    return super().execute(query, params)
           ^^^^^^^^^^^^^^^^^^^^^^^^^^^^^^
sqlite3.OperationalError: no such table: myapp_blogpost

The above exception was the direct cause of the following exception:

Traceback (most recent call last):
  File "/Library/Frameworks/Python.framework/Versions/3.11/lib/python3.11/site-packages/django/core/handlers/exception.py", line 55, in inner
    response = get_response(request)
               ^^^^^^^^^^^^^^^^^^^^^
  File "/Library/Frameworks/Python.framework/Versions/3.11/lib/python3.11/site-packages/django/core/handlers/base.py", line 197, in _get_response
    response = wrapped_callback(request, *callback_args, **callback_kwargs)
               ^^^^^^^^^^^^^^^^^^^^^^^^^^^^^^^^^^^^^^^^^^^^^^^^^^^^^^^^^^^^
  File "/Library/Frameworks/Python.framework/Versions/3.11/lib/python3.11/site-packages/django/views/generic/base.py", line 104, in view
    return self.dispatch(request, *args, **kwargs)
           ^^^^^^^^^^^^^^^^^^^^^^^^^^^^^^^^^^^^^^^
  File "/Library/Frameworks/Python.framework/Versions/3.11/lib/python3.11/site-packages/django/views/generic/base.py", line 143, in dispatch
    return handler(request, *args, **kwargs)
           ^^^^^^^^^^^^^^^^^^^^^^^^^^^^^^^^^
  File "/Users/tako/Desktop/step/django/hw_13_10_5/myproject/myapp/views.py", line 48, in get
    return render(request, 'blog_post_list.html', {'posts': posts})
           ^^^^^^^^^^^^^^^^^^^^^^^^^^^^^^^^^^^^^^^^^^^^^^^^^^^^^^^^
  File "/Library/Frameworks/Python.framework/Versions/3.11/lib/python3.11/site-packages/django/shortcuts.py", line 24, in render
    content = loader.render_to_string(template_name, context, request, using=using)
              ^^^^^^^^^^^^^^^^^^^^^^^^^^^^^^^^^^^^^^^^^^^^^^^^^^^^^^^^^^^^^^^^^^^^^
  File "/Library/Frameworks/Python.framework/Versions/3.11/lib/python3.11/site-packages/django/template/loader.py", line 62, in render_to_string
    return template.render(context, request)
           ^^^^^^^^^^^^^^^^^^^^^^^^^^^^^^^^^
  File "/Library/Frameworks/Python.framework/Versions/3.11/lib/python3.11/site-packages/django/template/backends/django.py", line 61, in render
    return self.template.render(context)
           ^^^^^^^^^^^^^^^^^^^^^^^^^^^^^
  File "/Library/Frameworks/Python.framework/Versions/3.11/lib/python3.11/site-packages/django/template/base.py", line 175, in render
    return self._render(context)
           ^^^^^^^^^^^^^^^^^^^^^
  File "/Library/Frameworks/Python.framework/Versions/3.11/lib/python3.11/site-packages/django/template/base.py", line 167, in _render
    return self.nodelist.render(context)
           ^^^^^^^^^^^^^^^^^^^^^^^^^^^^^
  File "/Library/Frameworks/Python.framework/Versions/3.11/lib/python3.11/site-packages/django/template/base.py", line 1005, in render
    return SafeString("".join([node.render_annotated(context) for node in self]))
                              ^^^^^^^^^^^^^^^^^^^^^^^^^^^^^^^^^^^^^^^^^^^^^^^^^
  File "/Library/Frameworks/Python.framework/Versions/3.11/lib/python3.11/site-packages/django/template/base.py", line 1005, in <listcomp>
    return SafeString("".join([node.render_annotated(context) for node in self]))
                               ^^^^^^^^^^^^^^^^^^^^^^^^^^^^^^
  File "/Library/Frameworks/Python.framework/Versions/3.11/lib/python3.11/site-packages/django/template/base.py", line 966, in render_annotated
    return self.render(context)
           ^^^^^^^^^^^^^^^^^^^^
  File "/Library/Frameworks/Python.framework/Versions/3.11/lib/python3.11/site-packages/django/template/defaulttags.py", line 194, in render
    len_values = len(values)
                 ^^^^^^^^^^^
  File "/Library/Frameworks/Python.framework/Versions/3.11/lib/python3.11/site-packages/django/db/models/query.py", line 380, in __len__
    self._fetch_all()
  File "/Library/Frameworks/Python.framework/Versions/3.11/lib/python3.11/site-packages/django/db/models/query.py", line 1881, in _fetch_all
    self._result_cache = list(self._iterable_class(self))
                         ^^^^^^^^^^^^^^^^^^^^^^^^^^^^^^^^
  File "/Library/Frameworks/Python.framework/Versions/3.11/lib/python3.11/site-packages/django/db/models/query.py", line 91, in __iter__
    results = compiler.execute_sql(
              ^^^^^^^^^^^^^^^^^^^^^
  File "/Library/Frameworks/Python.framework/Versions/3.11/lib/python3.11/site-packages/django/db/models/sql/compiler.py", line 1560, in execute_sql
    cursor.execute(sql, params)
  File "/Library/Frameworks/Python.framework/Versions/3.11/lib/python3.11/site-packages/django/db/backends/utils.py", line 102, in execute
    return super().execute(sql, params)
           ^^^^^^^^^^^^^^^^^^^^^^^^^^^^
  File "/Library/Frameworks/Python.framework/Versions/3.11/lib/python3.11/site-packages/django/db/backends/utils.py", line 67, in execute
    return self._execute_with_wrappers(
           ^^^^^^^^^^^^^^^^^^^^^^^^^^^^
  File "/Library/Frameworks/Python.framework/Versions/3.11/lib/python3.11/site-packages/django/db/backends/utils.py", line 80, in _execute_with_wrappers
    return executor(sql, params, many, context)
           ^^^^^^^^^^^^^^^^^^^^^^^^^^^^^^^^^^^^
  File "/Library/Frameworks/Python.framework/Versions/3.11/lib/python3.11/site-packages/django/db/backends/utils.py", line 84, in _execute
    with self.db.wrap_database_errors:
  File "/Library/Frameworks/Python.framework/Versions/3.11/lib/python3.11/site-packages/django/db/utils.py", line 91, in __exit__
    raise dj_exc_value.with_traceback(traceback) from exc_value
  File "/Library/Frameworks/Python.framework/Versions/3.11/lib/python3.11/site-packages/django/db/backends/utils.py", line 89, in _execute
    return self.cursor.execute(sql, params)
           ^^^^^^^^^^^^^^^^^^^^^^^^^^^^^^^^
  File "/Library/Frameworks/Python.framework/Versions/3.11/lib/python3.11/site-packages/django/db/backends/sqlite3/base.py", line 328, in execute
    return super().execute(query, params)
           ^^^^^^^^^^^^^^^^^^^^^^^^^^^^^^
django.db.utils.OperationalError: no such table: myapp_blogpost
"GET /blog_posts/ HTTP/1.1" 500 169539
Watching for file changes with StatReloader
Watching for file changes with StatReloader
"GET / HTTP/1.1" 200 251
"GET /blog_posts HTTP/1.1" 301 0
"GET /blog_posts/ HTTP/1.1" 200 192
/Users/tako/Desktop/step/django/hw_13_10_5/myproject/myapp/urls.py changed, reloading.
Watching for file changes with StatReloader
/Users/tako/Desktop/step/django/hw_13_10_5/myproject/myapp/urls.py changed, reloading.
Watching for file changes with StatReloader
